Loading rhel8/default-icl
  Loading requirement: dot rhel8/slurm singularity/current rhel8/global
    cuda/11.4 vgl/2.5.1/64 intel-oneapi-compilers/2022.1.0/gcc/b6zld2mz
    intel-oneapi-mpi/2021.6.0/intel/guxuvcpm
Changed directory to /rds/user/cm2121/hpc-work/dissertation-ibc.

JobID: 49503208
======
Time: Tue Apr  2 15:28:45 BST 2024
Running on master node: cpu-q-208
Current directory: /rds/user/cm2121/hpc-work/dissertation-ibc

Nodes allocated:
================
cpu-q-208

numtasks=1, numnodes=1, mpi_tasks_per_node=1 (OMP_NUM_THREADS=1)

Executing command:
==================
python -m hpc.run_dataset slashdot-threads -r 1000 -p iCentral_p >hpc/slurm/slashdot-threads/slashdot-threads-iCentral_p.txt

flatpak: symbol lookup error: /lib64/libk5crypto.so.3: undefined symbol: EVP_KDF_ctrl, version OPENSSL_1_1_1b
Process Process-2:
/var/spool/slurm/slurmd/job49503208/slurm_script: line 137: 844672 Killed                  python -m hpc.run_dataset slashdot-threads -r 1000 -p iCentral_p > hpc/slurm/slashdot-threads/slashdot-threads-iCentral_p.txt
Process Process-3:
Process Process-4:
Traceback (most recent call last):
  File "/home/cm2121/.conda/envs/main/lib/python3.10/multiprocessing/managers.py", line 810, in _callmethod
    conn = self._tls.connection
AttributeError: 'ForkAwareLocal' object has no attribute 'connection'

During handling of the above exception, another exception occurred:

Traceback (most recent call last):
  File "/home/cm2121/.conda/envs/main/lib/python3.10/multiprocessing/process.py", line 315, in _bootstrap
    self.run()
  File "/home/cm2121/.conda/envs/main/lib/python3.10/multiprocessing/process.py", line 108, in run
    self._target(*self._args, **self._kwargs)
  File "/rds/user/cm2121/hpc-work/dissertation-ibc/src/iCentral_p.py", line 80, in run
    bc_manager[k] += v
  File "<string>", line 2, in __getitem__
  File "/home/cm2121/.conda/envs/main/lib/python3.10/multiprocessing/managers.py", line 814, in _callmethod
    self._connect()
  File "/home/cm2121/.conda/envs/main/lib/python3.10/multiprocessing/managers.py", line 801, in _connect
    conn = self._Client(self._token.address, authkey=self._authkey)
  File "/home/cm2121/.conda/envs/main/lib/python3.10/multiprocessing/connection.py", line 507, in Client
    c = SocketClient(address)
  File "/home/cm2121/.conda/envs/main/lib/python3.10/multiprocessing/connection.py", line 635, in SocketClient
    s.connect(address)
ConnectionRefusedError: [Errno 111] Connection refused
slurmstepd: error: Detected 3 oom_kill events in StepId=49503208.batch. Some of the step tasks have been OOM Killed.
